Workbook

Sheet 0. Process Map
B2: Master Facility Readiness Scores
B3: Every score below is computed by a live formula that traces back to the raw field data. Nothing is hand-typed.
B5: STEP 1: DATASETS (raw, as collected)
B6: Sheet 1 · Data - Facilities | D6: 37 facility records | E6: Key indicators extracted from the 645-column General Assessment
B7: Sheet 2 · Data - Literacy Tests | D7: 162 staff tests | E7: Digital Literacy Assessment, scored 0–100 (Google Forms)
B8: Sheet 3 · Data - Staff Sentiment | D8: 186 staff responses | E8: Staff Sentiment Survey (anonymous, KoboToolbox)
B9: STEP 2: CLEAN & AGGREGATE (manual process made visible)
B10: Sheet 4 · Aggregate - Literacy | D10: COUNTIF / AVERAGEIF | E10: Mean DLA score & respondent count per facility, from Sheet 2
B11: Sheet 5 · Aggregate - Sentiment | D11: COUNTIF / AVERAGEIF | E11: Mean enthusiasm & count per facility, from Sheet 3
B12: STEP 3: SCORE (the engine — open any cell to see the formula)
B13: Sheet 6 · Scoring Engine | D13: nested IF formulas | E13: Pulls raw inputs + aggregates → 6 domain scores (0–3) → 6 blocker flags → composite → tier
B14: STEP 4: PRESENT & ROLL UP
B15: Sheet 7 · Facility Scorecards | D15: references Sheet 6 | E15: Ranked, colour-coded scorecard for each facility
B16: Sheet 8 · County Summary | D16: COUNTIFS / AVERAGEIF | E16: Tier mix & domain averages by county
B17: Sheet 9 · Cluster Summary | D17: COUNTIFS / AVERAGEIF | E17: Tier mix & domain averages by field cluster
B18: Sheet 10 · Blocker Register | D18: references Sheet 6 | E18: Every blocked facility + remediation pathway
B20: HEADLINE (live — counts the tiers on Sheet 7)
B21: Tier 1 — HOS-Ready | D21: =COUNTIF('7. Facility Scorecards'!M:M,"Tier 1") -> 1
B22: Tier 2 — Eligible w/ targeted investment | D22: =COUNTIF('7. Facility Scorecards'!M:M,"Tier 2") -> 13
B23: Tier 3 — Not deployment-ready (blocked) | D23: =COUNTIF('7. Facility Scorecards'!M:M,"Tier 3") -> 23
B24: Mean composite (of 100) | D24: =ROUND(AVERAGE('7. Facility Scorecards'!L2:L38),1) -> 59.1
B25: Facilities scored | D25: =COUNTA('7. Facility Scorecards'!B2:B38) -> 37

Sheet 1. Data - Facilities
A1: Facility | B1: County | C1: Type | D1: Lat | E1: Lon | F1: Power source | G1: Outage hrs/wk | H1: UPS | I1: Backup system | J1: Internet type | K1: Download Mbps | L1: Upload Mbps | M1: Uptime % | N1: Latency | O1: Mobile signal | P1: Laptops | Q1: Desktops | R1: Tablets | S1: Networking devices | T1: In-survey literacy % | U1: Health Centerian documents? | V1: Dedicated IT support? | W1: Support channel (Ops) | X1: Record method | Y1: On-time reporting | Z1: Client ID | AA1: DHIS2 reporting | AB1: Operational?
A2: Bahn Health Center | B2: Nimba | C2: Health Center | D2: 7.03 | E2: -8.73 | F2: Grid | G2: 16 | I2: Generator only | J2: Starlink | K2: 195.41 | L2: 16.03 | M2: 99 | N2: Low / stable (<80ms) | O2: Weak (-85 to -100 dBm) | P2: 3 | Q2: 0 | R2: 0 | S2: 4 | T2: 72 | U2: Some Health Centerians | V2: No | W2: Exists but inconsistent usage | X2: Paper only | Y2: >=90% on time | Z2: Yes - routinely | AA2: Yes - consistently | AB2: Yes
A3: Barnersville HC | B3: Montserrado | C3: Health Center | D3: 6.37 | E3: -10.73 | F3: Grid | G3: 3.99 | H3: Some workstations | I3: Multiple backup systems (specify below) | O3: Weak (-85 to -100 dBm) | P3: 1 | Q3: 1 | R3: 1 | S3: 1 | T3: 78 | U3: No - No Health Centerian | V3: No | W3: Integrated and routine | X3: Paper only | Y3: >=90% on time | Z3: Yes - routinely | AA3: Yes - consistently | AB3: Yes
A4: Boegeezay Health Center | B4: River Cess | C4: Health Center | D4: 6.15 | E4: -9.32 | F4: Solar / Inverter | G4: 24 | H4: All critical workstations | O4: Weak (-85 to -100 dBm) | P4: 1 | Q4: 0 | R4: 1 | S4: 0 | T4: 74 | U4: No - No Health Centerian | V4: No | W4: Integrated and routine | X4: Paper only | Y4: >=90% on time | Z4: Yes - routinely | AA4: Yes - consistently | AB4: Yes
A5: Bromely Community Health Center | B5: Montserrado | C5: Health Center | D5: 6.41 | E5: -10.74 | G5: 0 | O5: Moderate (-70 to -85 dBm) | P5: 0 | Q5: 0 | R5: 0 | S5: 0 | T5: 73 | U5: No - No Health Centerian | V5: No | X5: Paper only | Y5: >=90% on time | Z5: Yes - routinely | AA5: Yes - consistently | AB5: Yes
A6: Chocolate City HC | B6: Montserrado | C6: Health Center | D6: 6.33 | E6: -10.75 | F6: Grid | G6: 15 | I6: Solar / Inverter only | O6: Weak (-85 to -100 dBm) | P6: 1 | Q6: 0 | R6: 0 | S6: 0 | T6: 74 | U6: No - No Health Centerian | V6: No | W6: Integrated and routine | X6: Paper only | Y6: >=90% on time | Z6: Yes - routinely | AA6: Yes - consistently | AB6: Yes
A7: Clara Town Health Center | B7: Montserrado | C7: Health Center | D7: 6.33 | E7: -10.8 | F7: Grid | G7: 28 | I7: Generator only | O7: Weak (-85 to -100 dBm) | P7: 1 | Q7: 2 | R7: 0 | S7: 0 | T7: 72 | U7: No - No Health Centerian | V7: No | W7: Integrated and routine | X7: Paper only | Y7: >=90% on time | Z7: Yes - routinely | AA7: Yes - consistently | AB7: Yes
A8: Cotton Tree Health Center | B8: Margibi | C8: Health Center | D8: 6.29 | E8: -10.33 | F8: Grid | G8: 12 | I8: Generator only | O8: Moderate (-70 to -85 dBm) | P8: 0 | Q8: 0 | R8: 0 | S8: 0 | T8: 77 | U8: No - No Health Centerian | V8: No | X8: Paper only | Y8: 70-89% on time | Z8: Yes - routinely | AA8: Yes - consistently | AB8: Yes
A9: Damballa Health Center | B9: Grand Cape Mount | C9: Health Center | D9: 7.14 | E9: -11.28 | F9: Solar / Inverter | G9: 8 | O9: Weak (-85 to -100 dBm) | P9: 1 | Q9: 0 | R9: 0 | S9: 0 | T9: 60 | U9: No - No Health Centerian | V9: No | X9: Paper only | Y9: <70% on time | Z9: Yes - routinely | AA9: Yes - consistently | AB9: Yes
A10: Dolo's Town Health Center | B10: Margibi | C10: Health Center | D10: 6.25 | E10: -10.36 | F10: Grid | G10: 12 | I10: Generator only | O10: Strong (above -70 dBm) | P10: 4 | Q10: 0 | R10: 1 | S10: 0 | T10: 67 | U10: No - No Health Centerian | V10: No | X10: Paper only | Y10: >=90% on time | Z10: Yes - routinely | AA10: Yes - consistently | AB10: Yes
A11: Dr. Agnes Varis Health Center | B11: Montserrado | C11: Health Center | D11: 6.25 | E11: -10.68 | F11: Grid | G11: 18 | I11: Solar / Inverter only | O11: Strong (above -70 dBm) | P11: 1 | Q11: 0 | R11: 0 | S11: 0 | T11: 55 | U11: No - No Health Centerian | V11: No | X11: Paper only | Y11: >=90% on time | Z11: Yes - routinely | AA11: No | AB11: Yes
A12: Duport Road Health Center | B12: Montserrado | C12: Health Center | D12: 6.28 | E12: -10.69 | F12: Generator | G12: 16 | I12: Solar / Inverter only | O12: Moderate (-70 to -85 dBm) | P12: 4 | Q12: 2 | R12: 0 | S12: 0 | T12: 73 | U12: No - No Health Centerian | V12: Yes - part time / shared | X12: Paper only | Y12: 70-89% on time | Z12: Yes - routinely | AA12: No | AB12: Yes
A13: Foya Health Center | B13: Lofa | C13: Health Center | D13: 8.34 | E13: -10.2 | F13: Solar / Inverter | G13: 2 | H13: Some workstations | I13: Multiple backup systems (specify below) | O13: None (below -100 dBm or no signal) | P13: 3 | Q13: 2 | R13: 1 | S13: 0 | T13: 64 | U13: No - No Health Centerian | V13: No | W13: Exists but inconsistent usage | X13: Paper only | Y13: >=90% on time | Z13: Yes - routinely | AA13: Yes - consistently | AB13: Yes
A14: GW Harley Hospital | B14: Nimba | C14: Hospital | D14: 7.36 | E14: -8.71 | F14: Generator | G14: 4 | H14: Some workstations | I14: Multiple backup systems (specify below) | O14: None (below -100 dBm or no signal) | P14: 5 | Q14: 2 | R14: 0 | S14: 0 | T14: 78 | U14: No - No Health Centerian | V14: No | W14: Exists but inconsistent usage | X14: Paper only | Y14: >=90% on time | Z14: Yes - routinely | AA14: Yes - consistently | AB14: Yes
A15: Garzon Health Center | B15: Margibi | C15: Health Center | D15: 6.4 | E15: -10.43 | F15: Solar / Inverter | G15: 8 | I15: Generator only | O15: Moderate (-70 to -85 dBm) | P15: 0 | Q15: 0 | R15: 0 | S15: 0 | T15: 53 | U15: No - No Health Centerian | V15: No | X15: Paper only | Y15: 70-89% on time | Z15: Yes - routinely | AA15: Yes - consistently | AB15: Yes
A16: Gbarzon Health Center | B16: Grand Gedeh | C16: Health Center | D16: 6.23 | E16: -8.44 | F16: Solar / Inverter | G16: 5 | I16: Generator only | O16: Moderate (-70 to -85 dBm) | P16: 0 | Q16: 0 | R16: 0 | S16: 0 | T16: 60 | U16: No - No Health Centerian | V16: No | W16: Integrated and routine | X16: Paper only | Y16: 70-89% on time | Z16: Yes - routinely | AA16: Yes - consistently | AB16: Yes
A17: Gbeapo Health Center | B17: River Gee | C17: Health Center | D17: 5.23 | E17: -8.01 | F17: Solar / Inverter | G17: 20 | J17: 3G Wi-Fi Starlink | K17: 5.81 | L17: 11 | M17: 50 | N17: Low / stable (<80ms) | O17: Weak (-85 to -100 dBm) | P17: 1 | Q17: 0 | R17: 0 | S17: 0 | T17: 66 | U17: No - No Health Centerian | V17: No | X17: Paper only | Y17: >=90% on time | Z17: No unique ID | AA17: No | AB17: Yes
A18: J N Davies Hospital | B18: Montserrado | C18: Hospital | D18: 6.3 | E18: -10.71 | F18: Generator | G18: 24 | I18: Generator only | J18: Starlink | K18: 20 | L18: 26.8 | M18: 80 | N18: High / unstable (>200ms) | O18: Moderate (-70 to -85 dBm) | P18: 10 | Q18: 4 | R18: 0 | S18: 4 | T18: 73 | U18: No - No Health Centerian | V18: No | W18: Integrated and routine | X18: Paper only | Y18: >=90% on time | Z18: Yes - routinely | AA18: Yes - consistently | AB18: Yes
A19: JJ Dossen Hospital | B19: Maryland | C19: Hospital | D19: 4.38 | E19: -7.71 | F19: Grid | G19: 8 | I19: Generator only | J19: 3G 4G Starlink | K19: 1.93 | L19: 1.78 | M19: 95 | N19: Low / stable (<80ms) | O19: Moderate (-70 to -85 dBm) | P19: 5 | Q19: 3 | R19: 0 | S19: 0 | T19: 56 | U19: No - No Health Centerian | V19: No | X19: Hybrid (paper + digital) | Y19: 70-89% on time | Z19: Yes - routinely | AA19: Yes - consistently | AB19: Yes
A20: Kakata Health Center | B20: Margibi | C20: Health Center | D20: 6.55 | E20: -10.33 | F20: Solar / Inverter | G20: 15 | I20: Multiple backup systems (specify below) | J20: 4G | K20: 9.03 | L20: 4.51 | M20: 100 | N20: Low / stable (<80ms) | O20: Strong (above -70 dBm) | P20: 2 | Q20: 1 | R20: 1 | S20: 2 | T20: 82 | U20: No - No Health Centerian | V20: No | W20: Integrated and routine | X20: Paper only | Y20: >=90% on time | Z20: Yes - Inconsistently | AA20: Yes - consistently | AB20: Yes
A21: Karnplay Health Center | B21: Nimba | C21: Health Center | D21: 7.26 | E21: -8.5 | F21: Grid | G21: 53 | I21: Multiple backup systems (specify below) | O21: None (below -100 dBm or no signal) | P21: 4 | Q21: 0 | R21: 2 | S21: 0 | T21: 82 | U21: No - No Health Centerian | V21: No | W21: Exists but inconsistent usage | X21: Paper only | Y21: 70-89% on time | Z21: Yes - routinely | AA21: Yes - consistently | AB21: Yes
A22: Konia Health Center | B22: Lofa | C22: Health Center | D22: 7.96 | E22: -9.54 | F22: Solar / Inverter | G22: 0 | O22: None (below -100 dBm or no signal) | P22: 3 | Q22: 1 | R22: 0 | S22: 0 | T22: 70 | U22: No - No Health Centerian | V22: No | W22: Exists but inconsistent usage | X22: Paper only | Y22: >=90% on time | Z22: Yes - routinely | AA22: Yes - consistently | AB22: Yes
A23: Konobo Health Center | B23: Grand Gedeh | C23: Health Center | D23: 5.77 | E23: -7.86 | F23: Solar / Inverter | G23: 40 | I23: Solar / Inverter only | O23: Weak (-85 to -100 dBm) | P23: 0 | Q23: 0 | R23: 0 | S23: 0 | T23: 66 | U23: No - No Health Centerian | V23: No | X23: Paper only | Y23: >=90% on time | Z23: No unique ID | AA23: No | AB23: Yes
A24: Lofa Bridge Health Center | B24: Grand Cape Mount | C24: Health Center | D24: 7.07 | E24: -10.88 | F24: Solar / Inverter | G24: 24 | H24: Some workstations | O24: Moderate (-70 to -85 dBm) | P24: 0 | Q24: 0 | R24: 0 | S24: 0 | T24: 76 | U24: No - No Health Centerian | V24: No | W24: Integrated and routine | X24: Paper only | Y24: 70-89% on time | Z24: Yes - routinely | AA24: Yes - consistently | AB24: Yes
A25: Marshall Health Center | B25: Margibi | C25: Health Center | D25: 6.15 | E25: -10.38 | F25: Grid | G25: 12 | I25: Generator only | O25: Moderate (-70 to -85 dBm) | P25: 0 | Q25: 0 | R25: 0 | S25: 0 | T25: 73 | U25: No - No Health Centerian | V25: No | X25: Paper only | Y25: >=90% on time | Z25: Yes - routinely | AA25: Yes - consistently | AB25: Yes
A26: Massaquoi Town Health Center | B26: Margibi | C26: Health Center | D26: 6.68 | E26: -10.18 | F26: Solar / Inverter | G26: 10 | I26: Multiple backup systems (specify below) | O26: Strong (above -70 dBm) | P26: 0 | Q26: 0 | R26: 1 | S26: 0 | T26: 60 | U26: No - No Health Centerian | V26: No | W26: Integrated and routine | X26: Paper only | Y26: >=90% on time | Z26: Yes - Inconsistently | AA26: Yes - consistently | AB26: Yes
A27: New Georgia Community Health Center | B27: Montserrado | C27: Health Center | D27: 6.35 | E27: -10.76 | F27: Grid | G27: 2.94 | I27: Generator only | O27: Weak (-85 to -100 dBm) | P27: 0 | Q27: 0 | R27: 0 | S27: 0 | T27: 66 | U27: No - No Health Centerian | V27: No | W27: Integrated and routine | X27: Paper only | Y27: >=90% on time | Z27: Yes - routinely | AA27: Yes - consistently | AB27: Yes
A28: Nyehn Health Center | B28: Montserrado | C28: Health Center | D28: 6.55 | E28: -10.49 | F28: Generator | G28: 6 | J28: Starlink | K28: 61.8 | L28: 22.4 | M28: 80 | N28: Moderate (80-200ms) | O28: Weak (-85 to -100 dBm) | P28: 1 | Q28: 0 | R28: 0 | S28: 2 | T28: 78 | U28: No - No Health Centerian | V28: No | W28: Integrated and routine | X28: Paper only | Y28: >=90% on time | Z28: Yes - Inconsistently | AA28: Yes - consistently | AB28: Yes
A29: Pipeline Health Center | B29: Montserrado | C29: Health Center | D29: 6.3 | E29: -10.69 | F29: Grid | G29: 6 | I29: Generator only | O29: Moderate (-70 to -85 dBm) | P29: 1 | Q29: 0 | R29: 0 | S29: 0 | T29: 73 | U29: No - No Health Centerian | V29: Yes - part time / shared | X29: Paper only | Y29: 70-89% on time | Z29: Yes - routinely | AA29: Yes - consistently | AB29: Yes
A30: Pleebo Health Center | B30: Maryland | C30: Health Center | D30: 4.6 | E30: -7.67 | F30: Generator | G30: 0 | I30: Multiple backup systems (specify below) | J30: 3G 4G Starlink Wi-Fi | K30: 11.98 | L30: 12.07 | M30: 100 | N30: Moderate (80-200ms) | O30: Moderate (-70 to -85 dBm) | P30: 6 | Q30: 2 | R30: 1 | S30: 0 | T30: 64 | U30: No - No Health Centerian | V30: No | X30: Hybrid (paper + digital) | Y30: >=90% on time | Z30: Yes - routinely | AA30: Partially | AB30: Yes
A31: RH Ferguson Health Center | B31: Montserrado | C31: Health Center | D31: 6.32 | E31: -10.73 | F31: Grid | G31: 42 | I31: Generator only | O31: Weak (-85 to -100 dBm) | P31: 2 | Q31: 0 | R31: 0 | S31: 0 | T31: 66 | U31: No - No Health Centerian | V31: No | W31: Integrated and routine | X31: Paper only | Y31: >=90% on time | Z31: Yes - routinely | AA31: Yes - consistently | AB31: Yes
A32: Sacleapea Comprehensive Health Center | B32: Nimba | C32: Health Center | D32: 6.98 | E32: -8.84 | F32: Grid | G32: 22 | I32: Generator only | O32: None (below -100 dBm or no signal) | P32: 7 | Q32: 2 | R32: 0 | S32: 0 | T32: 72 | U32: No - No Health Centerian | V32: No | W32: Exists but inconsistent usage | X32: Paper only | Y32: >=90% on time | Z32: Yes - routinely | AA32: Yes - consistently | AB32: Yes
A33: Sarbo Health Center | B33: River Gee | C33: Health Center | D33: 5.13 | E33: -7.73 | F33: Grid | G33: 68 | I33: Generator only | O33: None (below -100 dBm or no signal) | P33: 0 | Q33: 0 | R33: 0 | S33: 0 | T33: 70 | U33: No - No Health Centerian | V33: No | X33: Paper only | Y33: 70-89% on time | Z33: No unique ID | AA33: No | AB33: Yes
A34: Sinje Health Center | B34: Grand Cape Mount | C34: Health Center | D34: 6.82 | E34: -11.14 | F34: Solar / Inverter | G34: 0 | I34: Multiple backup systems (specify below) | O34: Weak (-85 to -100 dBm) | P34: 4 | Q34: 0 | R34: 0 | S34: 0 | T34: 78 | U34: No - No Health Centerian | V34: No | W34: Integrated and routine | X34: Paper only | Y34: >=90% on time | Z34: Yes - routinely | AA34: Yes - consistently | AB34: Yes
A35: Soniwen Health Center | B35: Montserrado | C35: Health Center | D35: 6.31 | E35: -10.8 | F35: Grid | G35: 21 | H35: Some workstations | I35: Solar / Inverter only | O35: Weak (-85 to -100 dBm) | P35: 2 | Q35: 0 | R35: 0 | S35: 0 | T35: 66 | U35: No - No Health Centerian | V35: No | W35: Integrated and routine | X35: Paper only | Y35: >=90% on time | Z35: Yes - routinely | AA35: Yes - consistently | AB35: Yes
A36: Unification Town Health Center | B36: Margibi | C36: Health Center | D36: 6.25 | E36: -10.35 | F36: Grid | G36: 24 | O36: Moderate (-70 to -85 dBm) | P36: 0 | Q36: 0 | R36: 0 | S36: 0 | T36: 45 | U36: No - No Health Centerian | V36: No | X36: Paper only | Y36: >=90% on time | Z36: Yes - Inconsistently | AA36: No | AB36: Yes
A37: Vahun Health Center | B37: Nimba | C37: Health Center | D37: 8.06 | E37: -10.5 | F37: Generator | G37: 140 | I37: Generator only | J37: Starlink | K37: 12.2 | L37: 3.77 | M37: 90 | N37: High / unstable (>200ms) | O37: None (below -100 dBm or no signal) | P37: 3 | Q37: 2 | R37: 0 | S37: 0 | T37: 84 | U37: No - No Health Centerian | V37: No | W37: Exists but inconsistent usage | X37: Paper only | Y37: >=90% on time | Z37: Yes - routinely | AA37: Yes - consistently | AB37: Yes
A38: WAHO Health Center | B38: Grand Cape Mount | C38: Health Center | D38: 7.01 | E38: -11.37 | F38: Solar / Inverter | G38: 24 | I38: Multiple backup systems (specify below) | O38: Weak (-85 to -100 dBm) | P38: 2 | Q38: 0 | R38: 1 | S38: 0 | T38: 70 | U38: No - No Health Centerian | V38: No | W38: Integrated and routine | X38: Paper only | Y38: >=90% on time | Z38: Yes - routinely | AA38: No | AB38: Yes

Sheet 2. Data - Literacy Tests
A1: Facility (standardised) | B1: County | C1: Role | D1: Score /100
A2: JJ Dossen Hospital | B2: Maryland | C2: Record Officer / Data Clerk / Registrar | D2: 80
A3: JJ Dossen Hospital | B3: Maryland | C3: Record Officer / Data Clerk / Registrar | D3: 60
A4: JJ Dossen Hospital | B4: Maryland | C4: Administrative / Management (HR, Logistics, Finance, etc.) | D4: 20
A5: JJ Dossen Hospital | B5: Maryland | C5: Record Officer / Data Clerk / Registrar | D5: 70
A6: JJ Dossen Hospital | B6: Maryland | C6: Record Officer / Data Clerk / Registrar | D6: 50
A7: GW Harley Hospital | B7: Nimba | C7: Administrative / Management (HR, Logistics, Finance, etc.) | D7: 90
A8: GW Harley Hospital | B8: Nimba | C8: Supply chain coordinator | D8: 90
A9: GW Harley Hospital | B9: Nimba | C9: Record Officer / Data Clerk / Registrar | D9: 80
A10: GW Harley Hospital | B10: Nimba | C10: Administrative / Management (HR, Logistics, Finance, etc.) | D10: 60
A11: GW Harley Hospital | B11: Nimba | C11: Administrative / Management (HR, Logistics, Finance, etc.) | D11: 70
A12: GW Harley Hospital | B12: Nimba | C12: Administrative / Management (HR, Logistics, Finance, etc.) | D12: 90
A13: Sinje Health Center | B13: Grand Cape Mount | C13: Nurse / Midwife | D13: 80
... A163: Clara Town Health Center | B163: Montserrado | C163: Lab / Pharmacy Staff | D163: 50
A164: Damballa Health Center | B164: Grand Cape Mount | D164: 70
A165: Damballa Health Center | B165: Grand Cape Mount | D165: 60
A166: Damballa Health Center | B166: Grand Cape Mount | D166: 50

Sheet 3. Data - Staff Sentiment
A1: Facility (standardised) | B1: County | C1: Role | D1: Enthusiasm 0–10 | E1: Mgmt support | F1: Documentation experience | G1: Last training
A2: GW Harley Hospital | B2: Nimba | C2: Record Officer / Data Clerk / Registrar | D2: 9 | E2: Not engaged | F2: Burdensome - A significant burden that takes time away from patients | G2: Never
A3: GW Harley Hospital | B3: Nimba | C3: Lab / Pharmacy Staff | D3: 10 | E3: Actively driving adoption | F3: Neutral - It is manageable alongside my Health Centeral duties | G3: More than 1 year ago
A4: GW Harley Hospital | B4: Nimba | C4: Nurse / Midwife | D4: 10 | E4: Actively driving adoption | F4: It's useful — It enables us deliver better care | G4: Never
A5: GW Harley Hospital | B5: Nimba | C5: Physician Assistant | D5: 6 | E5: Actively driving adoption | F5: Tolerable - It takes too long but I accept it is necessary | G5: More than 1 year ago
A6: GW Harley Hospital | B6: Nimba | C6: Administrative / Management (HR, Logistics, Finance, etc.) | D6: 9 | E6: Actively driving adoption | F6: It's useful — It enables us deliver better care | G6: More than 1 year ago
A7: JJ Dossen Hospital | B7: Maryland | C7: Administrative / Management (HR, Logistics, Finance, etc.) | D7: 8 | E7: Actively driving adoption | F7: Neutral - It is manageable alongside my Health Centeral duties | G7: More than 1 year ago
A8: JJ Dossen Hospital | B8: Maryland | C8: Record Officer / Data Clerk / Registrar | D8: 9 | E8: Not engaged | F8: Burdensome - A significant burden that takes time away from patients | G8: More than 1 year ago
A9: JJ Dossen Hospital | B9: Maryland | C9: Officer-In-Charge / Doctor / Medical Officer / Health Centeral Officer | D9: 10 | E9: Partially engaged | F9: Burdensome - A significant burden that takes time away from patients | G9: Never
A10: JJ Dossen Hospital | B10: Maryland | C10: Lab / Pharmacy Staff | D10: 8 | E10: Not engaged | F10: Burdensome - A significant burden that takes time away from patients | G10: Never
A11: JJ Dossen Hospital | B11: Maryland | C11: Lab / Pharmacy Staff | D11: 6 | E11: Not engaged | F11: Burdensome - A significant burden that takes time away from patients | G11: Never
A12: Pleebo Health Center | B12: Maryland | C12: Officer-In-Charge / Doctor / Medical Officer / Health Centeral Officer | D12: 10 | E12: Actively driving adoption | F12: Burdensome - A significant burden that takes time away from patients | G12: Within the last year
A13: Pleebo Health Center | B13: Maryland | C13: Record Officer / Data Clerk / Registrar | D13: 5 | E13: Not engaged | F13: Tolerable - It takes too long but I accept it is necessary | G13: Never
... A187: WAHO Health Center | B187: Grand Cape Mount | C187: Nurse / Midwife | D187: 10 | E187: Partially engaged | F187: Tolerable - It takes too long but I accept it is necessary | G187: Never

Sheet 4. Aggregate - Literacy
A1: Facility | B1: DLA tests (n) | C1: Mean DLA % | D1: Confidence
A2: Bahn Health Center | B2: =COUNTIF('2. Data - Literacy Tests'!$A:$A,A2) -> 5 | C2: =IF(B2>0,ROUND(AVERAGEIF('2. Data - Literacy Tests'!$A:$A,A2,'2. Data - Literacy Tests'!$D:$D),0),"") -> 72 | D2: =IF(B2>=3,"Valid","Indicative (n<3)") -> Valid
A3: Barnersville HC | B3: =COUNTIF('2. Data - Literacy Tests'!$A:$A,A3) -> 5 | C3: =IF(B3>0,ROUND(AVERAGEIF('2. Data - Literacy Tests'!$A:$A,A3,'2. Data - Literacy Tests'!$D:$D),0),"") -> 78 | D3: =IF(B3>=3,"Valid","Indicative (n<3)") -> Valid
A4: Boegeezay Health Center | B4: =COUNTIF('2. Data - Literacy Tests'!$A:$A,A4) -> 5 | C4: =IF(B4>0,ROUND(AVERAGEIF('2. Data - Literacy Tests'!$A:$A,A4,'2. Data - Literacy Tests'!$D:$D),0),"") -> 74 | D4: =IF(B4>=3,"Valid","Indicative (n<3)") -> Valid
A5: Bromely Community Health Center | B5: =COUNTIF('2. Data - Literacy Tests'!$A:$A,A5) -> 3 | C5: =IF(B5>0,ROUND(AVERAGEIF('2. Data - Literacy Tests'!$A:$A,A5,'2. Data - Literacy Tests'!$D:$D),0),"") -> 73 | D5: =IF(B5>=3,"Valid","Indicative (n<3)") -> Valid
A6: Chocolate City HC | B6: =COUNTIF('2. Data - Literacy Tests'!$A:$A,A6) -> 5 | C6: =IF(B6>0,ROUND(AVERAGEIF('2. Data - Literacy Tests'!$A:$A,A6,'2. Data - Literacy Tests'!$D:$D),0),"") -> 74 | D6: =IF(B6>=3,"Valid","Indicative (n<3)") -> Valid
A7: Clara Town Health Center | B7: =COUNTIF('2. Data - Literacy Tests'!$A:$A,A7) -> 5 | C7: =IF(B7>0,ROUND(AVERAGEIF('2. Data - Literacy Tests'!$A:$A,A7,'2. Data - Literacy Tests'!$D:$D),0),"") -> 72 | D7: =IF(B7>=3,"Valid","Indicative (n<3)") -> Valid
A8: Cotton Tree Health Center | B8: =COUNTIF('2. Data - Literacy Tests'!$A:$A,A8) -> 3 | C8: =IF(B8>0,ROUND(AVERAGEIF('2. Data - Literacy Tests'!$A:$A,A8,'2. Data - Literacy Tests'!$D:$D),0),"") -> 77 | D8: =IF(B8>=3,"Valid","Indicative (n<3)") -> Valid
A9: Damballa Health Center | B9: =COUNTIF('2. Data - Literacy Tests'!$A:$A,A9) -> 3 | C9: =IF(B9>0,ROUND(AVERAGEIF('2. Data - Literacy Tests'!$A:$A,A9,'2. Data - Literacy Tests'!$D:$D),0),"") -> 60 | D9: =IF(B9>=3,"Valid","Indicative (n<3)") -> Valid
A10: Dolo's Town Health Center | B10: =COUNTIF('2. Data - Literacy Tests'!$A:$A,A10) -> 3 | C10: =IF(B10>0,ROUND(AVERAGEIF('2. Data - Literacy Tests'!$A:$A,A10,'2. Data - Literacy Tests'!$D:$D),0),"") -> 67 | D10: =IF(B10>=3,"Valid","Indicative (n<3)") -> Valid
A11: Dr. Agnes Varis Health Center | B11: =COUNTIF('2. Data - Literacy Tests'!$A:$A,A11) -> 2 | C11: =IF(B11>0,ROUND(AVERAGEIF('2. Data - Literacy Tests'!$A:$A,A11,'2. Data - Literacy Tests'!$D:$D),0),"") -> 55 | D11: =IF(B11>=3,"Valid","Indicative (n<3)") -> Indicative (n<3)
A12: Duport Road Health Center | B12: =COUNTIF('2. Data - Literacy Tests'!$A:$A,A12) -> 3 | C12: =IF(B12>0,ROUND(AVERAGEIF('2. Data - Literacy Tests'!$A:$A,A12,'2. Data - Literacy Tests'!$D:$D),0),"") -> 63 | D12: =IF(B12>=3,"Valid","Indicative (n<3)") -> Valid
A13: Foya Health Center | B13: =COUNTIF('2. Data - Literacy Tests'!$A:$A,A13) -> 5 | C13: =IF(B13>0,ROUND(AVERAGEIF('2. Data - Literacy Tests'!$A:$A,A13,'2. Data - Literacy Tests'!$D:$D),0),"") -> 64 | D13: =IF(B13>=3,"Valid","Indicative (n<3)") -> Valid
... A38: WAHO Health Center | B38: =COUNTIF('2. Data - Literacy Tests'!$A:$A,A38) -> 6 | C38: =IF(B38>0,ROUND(AVERAGEIF('2. Data - Literacy Tests'!$A:$A,A38,'2. Data - Literacy Tests'!$D:$D),0),"") -> 73 | D38: =IF(B38>=3,"Valid","Indicative (n<3)") -> Valid

Sheet 5. Aggregate - Sentiment
A1: Facility | B1: Surveys (n) | C1: Mean enthusiasm 0–10 | D1: Confidence
A2: Bahn Health Center | B2: =COUNTIF('3. Data - Staff Sentiment'!$A:$A,A2) -> 5 | C2: =IF(B2>0,ROUND(AVERAGEIF('3. Data - Staff Sentiment'!$A:$A,A2,'3. Data - Staff Sentiment'!$D:$D),1),"") -> 10 | D2: =IF(B2>=3,"Valid","Indicative (n<3)") -> Valid
A3: Barnersville HC | B3: =COUNTIF('3. Data - Staff Sentiment'!$A:$A,A3) -> 5 | C3: =IF(B3>0,ROUND(AVERAGEIF('3. Data - Staff Sentiment'!$A:$A,A3,'3. Data - Staff Sentiment'!$D:$D),1),"") -> 9.8 | D3: =IF(B3>=3,"Valid","Indicative (n<3)") -> Valid
A4: Boegeezay Health Center | B4: =COUNTIF('3. Data - Staff Sentiment'!$A:$A,A4) -> 5 | C4: =IF(B4>0,ROUND(AVERAGEIF('3. Data - Staff Sentiment'!$A:$A,A4,'3. Data - Staff Sentiment'!$D:$D),1),"") -> 9.6 | D4: =IF(B4>=3,"Valid","Indicative (n<3)") -> Valid
A5: Bromely Community Health Center | B5: =COUNTIF('3. Data - Staff Sentiment'!$A:$A,A5) -> 6 | C5: =IF(B5>0,ROUND(AVERAGEIF('3. Data - Staff Sentiment'!$A:$A,A5,'3. Data - Staff Sentiment'!$D:$D),1),"") -> 6.5 | D5: =IF(B5>=3,"Valid","Indicative (n<3)") -> Valid
A6: Chocolate City HC | B6: =COUNTIF('3. Data - Staff Sentiment'!$A:$A,A6) -> 5 | C6: =IF(B6>0,ROUND(AVERAGEIF('3. Data - Staff Sentiment'!$A:$A,A6,'3. Data - Staff Sentiment'!$D:$D),1),"") -> 9.8 | D6: =IF(B6>=3,"Valid","Indicative (n<3)") -> Valid
A7: Clara Town Health Center | B7: =COUNTIF('3. Data - Staff Sentiment'!$A:$A,A7) -> 5 | C7: =IF(B7>0,ROUND(AVERAGEIF('3. Data - Staff Sentiment'!$A:$A,A7,'3. Data - Staff Sentiment'!$D:$D),1),"") -> 5 | D7: =IF(B7>=3,"Valid","Indicative (n<3)") -> Valid
A8: Cotton Tree Health Center | B8: =COUNTIF('3. Data - Staff Sentiment'!$A:$A,A8) -> 4 | C8: =IF(B8>0,ROUND(AVERAGEIF('3. Data - Staff Sentiment'!$A:$A,A8,'3. Data - Staff Sentiment'!$D:$D),1),"") -> 6 | D8: =IF(B8>=3,"Valid","Indicative (n<3)") -> Valid
A9: Damballa Health Center | B9: =COUNTIF('3. Data - Staff Sentiment'!$A:$A,A9) -> 9 | C9: =IF(B9>0,ROUND(AVERAGEIF('3. Data - Staff Sentiment'!$A:$A,A9,'3. Data - Staff Sentiment'!$D:$D),1),"") -> 5.3 | D9: =IF(B9>=3,"Valid","Indicative (n<3)") -> Valid
A10: Dolo's Town Health Center | B10: =COUNTIF('3. Data - Staff Sentiment'!$A:$A,A10) -> 6 | C10: =IF(B10>0,ROUND(AVERAGEIF('3. Data - Staff Sentiment'!$A:$A,A10,'3. Data - Staff Sentiment'!$D:$D),1),"") -> 7.3 | D10: =IF(B10>=3,"Valid","Indicative (n<3)") -> Valid
A11: Dr. Agnes Varis Health Center | B11: =COUNTIF('3. Data - Staff Sentiment'!$A:$A,A11) -> 4 | C11: =IF(B11>0,ROUND(AVERAGEIF('3. Data - Staff Sentiment'!$A:$A,A11,'3. Data - Staff Sentiment'!$D:$D),1),"") -> 8.8 | D11: =IF(B11>=3,"Valid","Indicative (n<3)") -> Valid
A12: Duport Road Health Center | B12: =COUNTIF('3. Data - Staff Sentiment'!$A:$A,A12) -> 4 | C12: =IF(B12>0,ROUND(AVERAGEIF('3. Data - Staff Sentiment'!$A:$A,A12,'3. Data - Staff Sentiment'!$D:$D),1),"") -> 9.8 | D12: =IF(B12>=3,"Valid","Indicative (n<3)") -> Valid
A13: Foya Health Center | B13: =COUNTIF('3. Data - Staff Sentiment'!$A:$A,A13) -> 5 | C13: =IF(B13>0,ROUND(AVERAGEIF('3. Data - Staff Sentiment'!$A:$A,A13,'3. Data - Staff Sentiment'!$D:$D),1),"") -> 10 | D13: =IF(B13>=3,"Valid","Indicative (n<3)") -> Valid
... A38: WAHO Health Center | B38: =COUNTIF('3. Data - Staff Sentiment'!$A:$A,A38) -> 3 | C38: =IF(B38>0,ROUND(AVERAGEIF('3. Data - Staff Sentiment'!$A:$A,A38,'3. Data - Staff Sentiment'!$D:$D),1),"") -> 10 | D38: =IF(B38>=3,"Valid","Indicative (n<3)") -> Valid

Sheet 6. Scoring Engine
A1: Facility | B1: County | C1: Type | D1: Power src | E1: Outage/wk | F1: UPS | G1: Backup | H1: Internet | I1: Download | J1: Upload | K1: Uptime | L1: Latency | M1: Mobile sig | N1: Laptops | O1: Desktops | P1: Tablets | Q1: Net dev | R1: In-survey lit | S1: Health Centerian doc | T1: IT support | U1: Support chan | V1: Record method | W1: On-time rep | X1: Client ID | Y1: DHIS2 rep | Z1: Operational | AA1: DLA mean | AB1: DLA n | AC1: Enthus mean | AD1: Sent n | AE1: Eff. literacy | AF1: Device total | AG1: Download band | AH1: D-POW | AI1: D-CON | AJ1: D-ICT | AK1: D-DIG | AL1: D-SEN | AM1: D-DAT | AN1: BLK-01 | AO1: BLK-02 | AP1: BLK-03 | AQ1: BLK-04 | AR1: BLK-05 | AS1: BLK-06 | AT1: # Blockers | AU1: Blocker list | AV1: Blocker exp | AW1: COMPOSITE | AX1: TIER | AY1: WAVE
A2: ='1. Data - Facilities'!A2 -> Bahn Health Center | B2: ='1. Data - Facilities'!B2 -> Nimba | C2: ='1. Data - Facilities'!C2 -> Health Center | D2: ='1. Data - Facilities'!F2 -> Grid | E2: ='1. Data - Facilities'!G2 -> 16 | F2: ='1. Data - Facilities'!H2 | G2: ='1. Data - Facilities'!I2 -> Generator only | H2: ='1. Data - Facilities'!J2 -> Starlink | I2: ='1. Data - Facilities'!K2 -> 195.41 | J2: ='1. Data - Facilities'!L2 -> 16.03 | K2: ='1. Data - Facilities'!M2 -> 99 | ... Z2: ='1. Data - Facilities'!AB2 -> Yes | AA2: ='4. Aggregate - Literacy'!C2 -> 72 | AB2: ='4. Aggregate - Literacy'!B2 -> 5 | AC2: ='5. Aggregate - Sentiment'!C2 -> 10 | AD2: ='5. Aggregate - Sentiment'!B2 -> 5 | AE2: =IF(AND(AA2<>"",AB2>=3),AA2,R2) -> 72 | AF2: =N2+O2+P2 -> 3 | AG2: =IF(H2="","Mobile-only",IF(I2="","-",IF(I2>20,"High",IF(I2>=5,"Moderate","Low")))) -> High | AH2: =IF(OR(D2="",D2="None"),0,IF(AND(OR(D2="Grid",D2="Solar / Inverter"),E2<>"",E2<4,F2="All critical workstations"),3,IF(AND(E2<>"",E2>15,OR(G2="",G2="None")),1,IF(AND(D2="Generator",OR(G2="",G2="None")),1,IF(AND(OR(D2="Grid",D2="Solar / Inverter",D2="Generator"),OR(AND(G2<>"",G2<>"None"),AND(E2<>"",E2<=15))),2,1))))) -> 2 | AI2: =IF(AND(H2="",OR(LEFT(M2,4)="None",M2="")),0,IF(AND(H2<>"",I2<>"",I2<2),0,IF(AND(H2<>"",I2<>""),IF(AND(I2>20,J2<>"",J2>10,OR(K2="",K2>=90),ISNUMBER(SEARCH("Low",L2))),3,IF(I2>=5,2,1)),IF(OR(LEFT(M2,5)="Stron",LEFT(M2,4)="Mode"),2,IF(LEFT(M2,4)="Weak",1,1))))) -> 3 | AJ2: =IF(AND(N2+O2=0,P2=0),0,IF(OR(N2+O2>=3,P2>=5),IF(Q2>0,3,2),IF(OR(N2+O2>=1,P2>=2),2,1))) -> 3 | AK2: =IF(AND(ISNUMBER(AE2),AE2>=70,S2<>"Some Clinicians",LEFT(T2,3)="Yes"),3,IF(AND(ISNUMBER(AE2),AE2>=50),2,1)) -> 2 | AL2: =IF(AND(ISNUMBER(AC2),AC2>=5),2,IF(AND(ISNUMBER(AC2),AC2>=3),1,1)) -> 2 | AM2: =IF(AND(OR(ISNUMBER(SEARCH("Hybrid",V2)),ISNUMBER(SEARCH("Digital",V2))),ISNUMBER(SEARCH(">=90",W2)),ISNUMBER(SEARCH("routinely",X2))),3,IF(AND(ISNUMBER(SEARCH("Yes",X2)),OR(ISNUMBER(SEARCH("70-89",W2)),ISNUMBER(SEARCH(">=90",W2)))),2,IF(OR(ISNUMBER(SEARCH("Inconsistently",X2)),ISNUMBER(SEARCH("70-89",W2))),2,IF(ISNUMBER(SEARCH("No unique",X2)),1,1)))) -> 2 | AN2: =IF(AH2=0,1,0) -> 0 | AO2: =IF(AI2=0,1,0) -> 0 | AP2: =IF(AJ2=0,1,0) -> 0 | AQ2: =IF(Y2="No",1,0) -> 0 | AR2: =IF(AND(T2="No",U2=""),1,0) -> 0 | AS2: =IF(Z2<>"Yes",1,0) -> 0 | AT2: =SUM(AN2:AS2) -> 0 | AU2: =TRIM(IF(AN2=1,"BLK-01 ","")&IF(AO2=1,"BLK-02 ","")&IF(AP2=1,"BLK-03 ","")&IF(AQ2=1,"BLK-04 ","")&IF(AR2=1,"BLK-05 ","")&IF(AS2=1,"BLK-06 ","")) | AV2: =TRIM(IF(AN2=1,"BLK-01: No primary power | ","")&IF(AO2=1,"BLK-02: No connectivity / <2 Mbps | ","")&IF(AP2=1,"BLK-03: Zero computers or tablets | ","")&IF(AQ2=1,"BLK-04: Not reporting to DHIS2 | ","")&IF(AR2=1,"BLK-05: No IT support | ","")&IF(AS2=1,"BLK-06: Not operational | ","")) | AW2: =ROUND((AH2*22+AI2*18+AJ2*13+AK2*22+AL2*15+AM2*10)/300*100,1) -> 77 | AX2: =IF(AT2>0,"Tier 3",IF(AW2>=75,"Tier 1","Tier 2")) -> Tier 1 | AY2: =IF(AT2>0,"—",IF(AW2>=75,"Wave 1","Wave 2")) -> Wave 1
A3: ='1. Data - Facilities'!A3 -> Barnersville HC | B3: ='1. Data - Facilities'!B3 -> Montserrado | C3: ='1. Data - Facilities'!C3 -> Health Center | D3: ='1. Data - Facilities'!F3 -> Grid | E3: ='1. Data - Facilities'!G3 -> 3.99 | F3: ='1. Data - Facilities'!H3 -> Some workstations | G3: ='1. Data - Facilities'!I3 -> Multiple backup systems (specify below) | H3: ='1. Data - Facilities'!J3 | I3: ='1. Data - Facilities'!K3 | J3: ='1. Data - Facilities'!L3 | K3: ='1. Data - Facilities'!M3 | ... Z3: ='1. Data - Facilities'!AB3 -> Yes | AA3: ='4. Aggregate - Literacy'!C3 -> 78 | AB3: ='4. Aggregate - Literacy'!B3 -> 5 | AC3: ='5. Aggregate - Sentiment'!C3 -> 9.8 | AD3: ='5. Aggregate - Sentiment'!B3 -> 5 | AE3: =IF(AND(AA3<>"",AB3>=3),AA3,R3) -> 78 | AF3: =N3+O3+P3 -> 3 | AG3: =IF(H3="","Mobile-only",IF(I3="","-",IF(I3>20,"High",IF(I3>=5,"Moderate","Low")))) -> Mobile-only | AH3: =IF(OR(D3="",D3="None"),0,IF(AND(OR(D3="Grid",D3="Solar / Inverter"),E3<>"",E3<4,F3="All critical workstations"),3,IF(AND(E3<>"",E3>15,OR(G3="",G3="None")),1,IF(AND(D3="Generator",OR(G3="",G3="None")),1,IF(AND(OR(D3="Grid",D3="Solar / Inverter",D3="Generator"),OR(AND(G3<>"",G3<>"None"),AND(E3<>"",E3<=15))),2,1))))) -> 2 | AI3: =IF(AND(H3="",OR(LEFT(M3,4)="None",M3="")),0,IF(AND(H3<>"",I3<>"",I3<2),0,IF(AND(H3<>"",I3<>""),IF(AND(I3>20,J3<>"",J3>10,OR(K3="",K3>=90),ISNUMBER(SEARCH("Low",L3))),3,IF(I3>=5,2,1)),IF(OR(LEFT(M3,5)="Stron",LEFT(M3,4)="Mode"),2,IF(LEFT(M3,4)="Weak",1,1))))) -> 1 | AJ3: =IF(AND(N3+O3=0,P3=0),0,IF(OR(N3+O3>=3,P3>=5),IF(Q3>0,3,2),IF(OR(N3+O3>=1,P3>=2),2,1))) -> 2 | AK3: =IF(AND(ISNUMBER(AE3),AE3>=70,S3<>"Some Clinicians",LEFT(T3,3)="Yes"),3,IF(AND(ISNUMBER(AE3),AE3>=50),2,1)) -> 2 | AL3: =IF(AND(ISNUMBER(AC3),AC3>=5),2,IF(AND(ISNUMBER(AC3),AC3>=3),1,1)) -> 2 | AM3: =IF(AND(OR(ISNUMBER(SEARCH("Hybrid",V3)),ISNUMBER(SEARCH("Digital",V3))),ISNUMBER(SEARCH(">=90",W3)),ISNUMBER(SEARCH("routinely",X3))),3,IF(AND(ISNUMBER(SEARCH("Yes",X3)),OR(ISNUMBER(SEARCH("70-89",W3)),ISNUMBER(SEARCH(">=90",W3)))),2,IF(OR(ISNUMBER(SEARCH("Inconsistently",X3)),ISNUMBER(SEARCH("70-89",W3))),2,IF(ISNUMBER(SEARCH("No unique",X3)),1,1)))) -> 2 | AN3: =IF(AH3=0,1,0) -> 0 | AO3: =IF(AI3=0,1,0) -> 0 | AP3: =IF(AJ3=0,1,0) -> 0 | AQ3: =IF(Y3="No",1,0) -> 0 | AR3: =IF(AND(T3="No",U3=""),1,0) -> 0 | AS3: =IF(Z3<>"Yes",1,0) -> 0 | AT3: =SUM(AN3:AS3) -> 0 | AU3: =TRIM(IF(AN3=1,"BLK-01 ","")&IF(AO3=1,"BLK-02 ","")&IF(AP3=1,"BLK-03 ","")&IF(AQ3=1,"BLK-04 ","")&IF(AR3=1,"BLK-05 ","")&IF(AS3=1,"BLK-06 ","")) | AV3: =TRIM(IF(AN3=1,"BLK-01: No primary power | ","")&IF(AO3=1,"BLK-02: No connectivity / <2 Mbps | ","")&IF(AP3=1,"BLK-03: Zero computers or tablets | ","")&IF(AQ3=1,"BLK-04: Not reporting to DHIS2 | ","")&IF(AR3=1,"BLK-05: No IT support | ","")&IF(AS3=1,"BLK-06: Not operational | ","")) | AW3: =ROUND((AH3*22+AI3*18+AJ3*13+AK3*22+AL3*15+AM3*10)/300*100,1) -> 60.7 | AX3: =IF(AT3>0,"Tier 3",IF(AW3>=75,"Tier 1","Tier 2")) -> Tier 2 | AY3: =IF(AT3>0,"—",IF(AW3>=75,"Wave 1","Wave 2")) -> Wave 2
A4: ='1. Data - Facilities'!A4 -> Boegeezay Health Center | B4: ='1. Data - Facilities'!B4 -> River Cess | C4: ='1. Data - Facilities'!C4 -> Health Center | D4: ='1. Data - Facilities'!F4 -> Solar / Inverter | E4: ='1. Data - Facilities'!G4 -> 24 | F4: ='1. Data - Facilities'!H4 -> All critical workstations | G4: ='1. Data - Facilities'!I4 | H4: ='1. Data - Facilities'!J4 | I4: ='1. Data - Facilities'!K4 | J4: ='1. Data - Facilities'!L4 | K4: ='1. Data - Facilities'!M4 | ... Z4: ='1. Data - Facilities'!AB4 -> Yes | AA4: ='4. Aggregate - Literacy'!C4 -> 74 | AB4: ='4. Aggregate - Literacy'!B4 -> 5 | AC4: ='5. Aggregate - Sentiment'!C4 -> 9.6 | AD4: ='5. Aggregate - Sentiment'!B4 -> 5 | AE4: =IF(AND(AA4<>"",AB4>=3),AA4,R4) -> 74 | AF4: =N4+O4+P4 -> 2 | AG4: =IF(H4="","Mobile-only",IF(I4="","-",IF(I4>20,"High",IF(I4>=5,"Moderate","Low")))) -> Mobile-only | AH4: =IF(OR(D4="",D4="None"),0,IF(AND(OR(D4="Grid",D4="Solar / Inverter"),E4<>"",E4<4,F4="All critical workstations"),3,IF(AND(E4<>"",E4>15,OR(G4="",G4="None")),1,IF(AND(D4="Generator",OR(G4="",G4="None")),1,IF(AND(OR(D4="Grid",D4="Solar / Inverter",D4="Generator"),OR(AND(G4<>"",G4<>"None"),AND(E4<>"",E4<=15))),2,1))))) -> 1 | AI4: =IF(AND(H4="",OR(LEFT(M4,4)="None",M4="")),0,IF(AND(H4<>"",I4<>"",I4<2),0,IF(AND(H4<>"",I4<>""),IF(AND(I4>20,J4<>"",J4>10,OR(K4="",K4>=90),ISNUMBER(SEARCH("Low",L4))),3,IF(I4>=5,2,1)),IF(OR(LEFT(M4,5)="Stron",LEFT(M4,4)="Mode"),2,IF(LEFT(M4,4)="Weak",1,1))))) -> 1 | AJ4: =IF(AND(N4+O4=0,P4=0),0,IF(OR(N4+O4>=3,P4>=5),IF(Q4>0,3,2),IF(OR(N4+O4>=1,P4>=2),2,1))) -> 2 | AK4: =IF(AND(ISNUMBER(AE4),AE4>=70,S4<>"Some Clinicians",LEFT(T4,3)="Yes"),3,IF(AND(ISNUMBER(AE4),AE4>=50),2,1)) -> 2 | AL4: =IF(AND(ISNUMBER(AC4),AC4>=5),2,IF(AND(ISNUMBER(AC4),AC4>=3),1,1)) -> 2 | AM4: =IF(AND(OR(ISNUMBER(SEARCH("Hybrid",V4)),ISNUMBER(SEARCH("Digital",V4))),ISNUMBER(SEARCH(">=90",W4)),ISNUMBER(SEARCH("routinely",X4))),3,IF(AND(ISNUMBER(SEARCH("Yes",X4)),OR(ISNUMBER(SEARCH("70-89",W4)),ISNUMBER(SEARCH(">=90",W4)))),2,IF(OR(ISNUMBER(SEARCH("Inconsistently",X4)),ISNUMBER(SEARCH("70-89",W4))),2,IF(ISNUMBER(SEARCH("No unique",X4)),1,1)))) -> 2 | AN4: =IF(AH4=0,1,0) -> 0 | AO4: =IF(AI4=0,1,0) -> 0 | AP4: =IF(AJ4=0,1,0) -> 0 | AQ4: =IF(Y4="No",1,0) -> 0 | AR4: =IF(AND(T4="No",U4=""),1,0) -> 0 | AS4: =IF(Z4<>"Yes",1,0) -> 0 | AT4: =SUM(AN4:AS4) -> 0 | AU4: =TRIM(IF(AN4=1,"BLK-01 ","")&IF(AO4=1,"BLK-02 ","")&IF(AP4=1,"BLK-03 ","")&IF(AQ4=1,"BLK-04 ","")&IF(AR4=1,"BLK-05 ","")&IF(AS4=1,"BLK-06 ","")) | AV4: =TRIM(IF(AN4=1,"BLK-01: No primary power | ","")&IF(AO4=1,"BLK-02: No connectivity / <2 Mbps | ","")&IF(AP4=1,"BLK-03: Zero computers or tablets | ","")&IF(AQ4=1,"BLK-04: Not reporting to DHIS2 | ","")&IF(AR4=1,"BLK-05: No IT support | ","")&IF(AS4=1,"BLK-06: Not operational | ","")) | AW4: =ROUND((AH4*22+AI4*18+AJ4*13+AK4*22+AL4*15+AM4*10)/300*100,1) -> 53.3 | AX4: =IF(AT4>0,"Tier 3",IF(AW4>=75,"Tier 1","Tier 2")) -> Tier 2 | AY4: =IF(AT4>0,"—",IF(AW4>=75,"Wave 1","Wave 2")) -> Wave 2
A5: ='1. Data - Facilities'!A5 -> Bromely Community Health Center | B5: ='1. Data - Facilities'!B5 -> Montserrado | C5: ='1. Data - Facilities'!C5 -> Health Center | D5: ='1. Data - Facilities'!F5 | E5: ='1. Data - Facilities'!G5 -> 0 | F5: ='1. Data - Facilities'!H5 | G5: ='1. Data - Facilities'!I5 | H5: ='1. Data - Facilities'!J5 | I5: ='1. Data - Facilities'!K5 | J5: ='1. Data - Facilities'!L5 | K5: ='1. Data - Facilities'!M5 | ... Z5: ='1. Data - Facilities'!AB5 -> Yes | AA5: ='4. Aggregate - Literacy'!C5 -> 73 | AB5: ='4. Aggregate - Literacy'!B5 -> 3 | AC5: ='5. Aggregate - Sentiment'!C5 -> 6.5 | AD5: ='5. Aggregate - Sentiment'!B5 -> 6 | AE5: =IF(AND(AA5<>"",AB5>=3),AA5,R5) -> 73 | AF5: =N5+O5+P5 -> 0 | AG5: =IF(H5="","Mobile-only",IF(I5="","-",IF(I5>20,"High",IF(I5>=5,"Moderate","Low")))) -> Mobile-only | AH5: =IF(OR(D5="",D5="None"),0,IF(AND(OR(D5="Grid",D5="Solar / Inverter"),E5<>"",E5<4,F5="All critical workstations"),3,IF(AND(E5<>"",E5>15,OR(G5="",G5="None")),1,IF(AND(D5="Generator",OR(G5="",G5="None")),1,IF(AND(OR(D5="Grid",D5="Solar / Inverter",D5="Generator"),OR(AND(G5<>"",G5<>"None"),AND(E5<>"",E5<=15))),2,1))))) -> 0 | AI5: =IF(AND(H5="",OR(LEFT(M5,4)="None",M5="")),0,IF(AND(H5<>"",I5<>"",I5<2),0,IF(AND(H5<>"",I5<>""),IF(AND(I5>20,J5<>"",J5>10,OR(K5="",K5>=90),ISNUMBER(SEARCH("Low",L5))),3,IF(I5>=5,2,1)),IF(OR(LEFT(M5,5)="Stron",LEFT(M5,4)="Mode"),2,IF(LEFT(M5,4)="Weak",1,1))))) -> 2 | AJ5: =IF(AND(N5+O5=0,P5=0),0,IF(OR(N5+O5>=3,P5>=5),IF(Q5>0,3,2),IF(OR(N5+O5>=1,P5>=2),2,1))) -> 0 | AK5: =IF(AND(ISNUMBER(AE5),AE5>=70,S5<>"Some Clinicians",LEFT(T5,3)="Yes"),3,IF(AND(ISNUMBER(AE5),AE5>=50),2,1)) -> 2 | AL5: =IF(AND(ISNUMBER(AC5),AC5>=5),2,IF(AND(ISNUMBER(AC5),AC5>=3),1,1)) -> 2 | AM5: =IF(AND(OR(ISNUMBER(SEARCH("Hybrid",V5)),ISNUMBER(SEARCH("Digital",V5))),ISNUMBER(SEARCH(">=90",W5)),ISNUMBER(SEARCH("routinely",X5))),3,IF(AND(ISNUMBER(SEARCH("Yes",X5)),OR(ISNUMBER(SEARCH("70-89",W5)),ISNUMBER(SEARCH(">=90",W5)))),2,IF(OR(ISNUMBER(SEARCH("Inconsistently",X5)),ISNUMBER(SEARCH("70-89",W5))),2,IF(ISNUMBER(SEARCH("No unique",X5)),1,1)))) -> 2 | AN5: =IF(AH5=0,1,0) -> 1 | AO5: =IF(AI5=0,1,0) -> 0 | AP5: =IF(AJ5=0,1,0) -> 1 | AQ5: =IF(Y5="No",1,0) -> 0 | AR5: =IF(AND(T5="No",U5=""),1,0) -> 1 | AS5: =IF(Z5<>"Yes",1,0) -> 0 | AT5: =SUM(AN5:AS5) -> 3 | AU5: =TRIM(IF(AN5=1,"BLK-01 ","")&IF(AO5=1,"BLK-02 ","")&IF(AP5=1,"BLK-03 ","")&IF(AQ5=1,"BLK-04 ","")&IF(AR5=1,"BLK-05 ","")&IF(AS5=1,"BLK-06 ","")) -> BLK-01 BLK-03 BLK-05 | AV5: =TRIM(IF(AN5=1,"BLK-01: No primary power | ","")&IF(AO5=1,"BLK-02: No connectivity / <2 Mbps | ","")&IF(AP5=1,"BLK-03: Zero computers or tablets | ","")&IF(AQ5=1,"BLK-04: Not reporting to DHIS2 | ","")&IF(AR5=1,"BLK-05: No IT support | ","")&IF(AS5=1,"BLK-06: Not operational | ","")) -> BLK-01: No primary power | BLK-03: Zero computers or tablets | BLK-05: No IT support | | AW5: =ROUND((AH5*22+AI5*18+AJ5*13+AK5*22+AL5*15+AM5*10)/300*100,1) -> 43.3 | AX5: =IF(AT5>0,"Tier 3",IF(AW5>=75,"Tier 1","Tier 2")) -> Tier 3 | AY5: =IF(AT5>0,"—",IF(AW5>=75,"Wave 1","Wave 2")) -> —
A6: ='1. Data - Facilities'!A6 -> Chocolate City HC | B6: ='1. Data - Facilities'!B6 -> Montserrado | C6: ='1. Data - Facilities'!C6 -> Health Center | D6: ='1. Data - Facilities'!F6 -> Grid | E6: ='1. Data - Facilities'!G6 -> 15 | F6: ='1. Data - Facilities'!H6 | G6: ='1. Data - Facilities'!I6 -> Solar / Inverter only | H6: ='1. Data - Facilities'!J6 | I6: ='1. Data - Facilities'!K6 | J6: ='1. Data - Facilities'!L6 | K6: ='1. Data - Facilities'!M6 | ... Z6: ='1. Data - Facilities'!AB6 -> Yes | AA6: ='4. Aggregate - Literacy'!C6 -> 74 | AB6: ='4. Aggregate - Literacy'!B6 -> 5 | AC6: ='5. Aggregate - Sentiment'!C6 -> 9.8 | AD6: ='5. Aggregate - Sentiment'!B6 -> 5 | AE6: =IF(AND(AA6<>"",AB6>=3),AA6,R6) -> 74 | AF6: =N6+O6+P6 -> 1 | AG6: =IF(H6="","Mobile-only",IF(I6="","-",IF(I6>20,"High",IF(I6>=5,"Moderate","Low")))) -> Mobile-only | AH6: =IF(OR(D6="",D6="None"),0,IF(AND(OR(D6="Grid",D6="Solar / Inverter"),E6<>"",E6<4,F6="All critical workstations"),3,IF(AND(E6<>"",E6>15,OR(G6="",G6="None")),1,IF(AND(D6="Generator",OR(G6="",G6="None")),1,IF(AND(OR(D6="Grid",D6="Solar / Inverter",D6="Generator"),OR(AND(G6<>"",G6<>"None"),AND(E6<>"",E6<=15))),2,1))))) -> 2 | AI6: =IF(AND(H6="",OR(LEFT(M6,4)="None",M6="")),0,IF(AND(H6<>"",I6<>"",I6<2),0,IF(AND(H6<>"",I6<>""),IF(AND(I6>20,J6<>"",J6>10,OR(K6="",K6>=90),ISNUMBER(SEARCH("Low",L6))),3,IF(I6>=5,2,1)),IF(OR(LEFT(M6,5)="Stron",LEFT(M6,4)="Mode"),2,IF(LEFT(M6,4)="Weak",1,1))))) -> 1 | AJ6: =IF(AND(N6+O6=0,P6=0),0,IF(OR(N6+O6>=3,P6>=5),IF(Q6>0,3,2),IF(OR(N6+O6>=1,P6>=2),2,1))) -> 2 | AK6: =IF(AND(ISNUMBER(AE6),AE6>=70,S6<>"Some Clinicians",LEFT(T6,3)="Yes"),3,IF(AND(ISNUMBER(AE6),AE6>=50),2,1)) -> 2 | AL6: =IF(AND(ISNUMBER(AC6),AC6>=5),2,IF(AND(ISNUMBER(AC6),AC6>=3),1,1)) -> 2 | AM6: =IF(AND(OR(ISNUMBER(SEARCH("Hybrid",V6)),ISNUMBER(SEARCH("Digital",V6))),ISNUMBER(SEARCH(">=90",W6)),ISNUMBER(SEARCH("routinely",X6))),3,IF(AND(ISNUMBER(SEARCH("Yes",X6)),OR(ISNUMBER(SEARCH("70-89",W6)),ISNUMBER(SEARCH(">=90",W6)))),2,IF(OR(ISNUMBER(SEARCH("Inconsistently",X6)),ISNUMBER(SEARCH("70-89",W6))),2,IF(ISNUMBER(SEARCH("No unique",X6)),1,1)))) -> 2 | AN6: =IF(AH6=0,1,0) -> 0 | AO6: =IF(AI6=0,1,0) -> 0 | AP6: =IF(AJ6=0,1,0) -> 0 | AQ6: =IF(Y6="No",1,0) -> 0 | AR6: =IF(AND(T6="No",U6=""),1,0) -> 0 | AS6: =IF(Z6<>"Yes",1,0) -> 0 | AT6: =SUM(AN6:AS6) -> 0 | AU6: =TRIM(IF(AN6=1,"BLK-01 ","")&IF(AO6=1,"BLK-02 ","")&IF(AP6=1,"BLK-03 ","")&IF(AQ6=1,"BLK-04 ","")&IF(AR6=1,"BLK-05 ","")&IF(AS6=1,"BLK-06 ","")) | AV6: =TRIM(IF(AN6=1,"BLK-01: No primary power | ","")&IF(AO6=1,"BLK-02: No connectivity / <2 Mbps | ","")&IF(AP6=1,"BLK-03: Zero computers or tablets | ","")&IF(AQ6=1,"BLK-04: Not reporting to DHIS2 | ","")&IF(AR6=1,"BLK-05: No IT support | ","")&IF(AS6=1,"BLK-06: Not operational | ","")) | AW6: =ROUND((AH6*22+AI6*18+AJ6*13+AK6*22+AL6*15+AM6*10)/300*100,1) -> 60.7 | AX6: =IF(AT6>0,"Tier 3",IF(AW6>=75,"Tier 1","Tier 2")) -> Tier 2 | AY6: =IF(AT6>0,"—",IF(AW6>=75,"Wave 1","Wave 2")) -> Wave 2
A7: ='1. Data - Facilities'!A7 -> Clara Town Health Center | B7: ='1. Data - Facilities'!B7 -> Montserrado | C7: ='1. Data - Facilities'!C7 -> Health Center | D7: ='1. Data - Facilities'!F7 -> Grid | E7: ='1. Data - Facilities'!G7 -> 28 | F7: ='1. Data - Facilities'!H7 | G7: ='1. Data - Facilities'!I7 -> Generator only | H7: ='1. Data - Facilities'!J7 | I7: ='1. Data - Facilities'!K7 | J7: ='1. Data - Facilities'!L7 | K7: ='1. Data - Facilities'!M7 | ... Z7: ='1. Data - Facilities'!AB7 -> Yes | AA7: ='4. Aggregate - Literacy'!C7 -> 72 | AB7: ='4. Aggregate - Literacy'!B7 -> 5 | AC7: ='5. Aggregate - Sentiment'!C7 -> 5 | AD7: ='5. Aggregate - Sentiment'!B7 -> 5 | AE7: =IF(AND(AA7<>"",AB7>=3),AA7,R7) -> 72 | AF7: =N7+O7+P7 -> 3 | AG7: =IF(H7="","Mobile-only",IF(I7="","-",IF(I7>20,"High",IF(I7>=5,"Moderate","Low")))) -> Mobile-only | AH7: =IF(OR(D7="",D7="None"),0,IF(AND(OR(D7="Grid",D7="Solar / Inverter"),E7<>"",E7<4,F7="All critical workstations"),3,IF(AND(E7<>"",E7>15,OR(G7="",G7="None")),1,IF(AND(D7="Generator",OR(G7="",G7="None")),1,IF(AND(OR(D7="Grid",D7="Solar / Inverter",D7="Generator"),OR(AND(G7<>"",G7<>"None"),AND(E7<>"",E7<=15))),2,1))))) -> 2 | AI7: =IF(AND(H7="",OR(LEFT(M7,4)="None",M7="")),0,IF(AND(H7<>"",I7<>"",I7<2),0,IF(AND(H7<>"",I7<>""),IF(AND(I7>20,J7<>"",J7>10,OR(K7="",K7>=90),ISNUMBER(SEARCH("Low",L7))),3,IF(I7>=5,2,1)),IF(OR(LEFT(M7,5)="Stron",LEFT(M7,4)="Mode"),2,IF(LEFT(M7,4)="Weak",1,1))))) -> 1 | AJ7: =IF(AND(N7+O7=0,P7=0),0,IF(OR(N7+O7>=3,P7>=5),IF(Q7>0,3,2),IF(OR(N7+O7>=1,P7>=2),2,1))) -> 2 | AK7: =IF(AND(ISNUMBER(AE7),AE7>=70,S7<>"Some Clinicians",LEFT(T7,3)="Yes"),3,IF(AND(ISNUMBER(AE7),AE7>=50),2,1)) -> 2 | AL7: =IF(AND(ISNUMBER(AC7),AC7>=5),2,IF(AND(ISNUMBER(AC7),AC7>=3),1,1)) -> 2 | AM7: =IF(AND(OR(ISNUMBER(SEARCH("Hybrid",V7)),ISNUMBER(SEARCH("Digital",V7))),ISNUMBER(SEARCH(">=90",W7)),ISNUMBER(SEARCH("routinely",X7))),3,IF(AND(ISNUMBER(SEARCH("Yes",X7)),OR(ISNUMBER(SEARCH("70-89",W7)),ISNUMBER(SEARCH(">=90",W7)))),2,IF(OR(ISNUMBER(SEARCH("Inconsistently",X7)),ISNUMBER(SEARCH("70-89",W7))),2,IF(ISNUMBER(SEARCH("No unique",X7)),1,1)))) -> 2 | AN7: =IF(AH7=0,1,0) -> 0 | AO7: =IF(AI7=0,1,0) -> 0 | AP7: =IF(AJ7=0,1,0) -> 0 | AQ7: =IF(Y7="No",1,0) -> 0 | AR7: =IF(AND(T7="No",U7=""),1,0) -> 0 | AS7: =IF(Z7<>"Yes",1,0) -> 0 | AT7: =SUM(AN7:AS7) -> 0 | AU7: =TRIM(IF(AN7=1,"BLK-01 ","")&IF(AO7=1,"BLK-02 ","")&IF(AP7=1,"BLK-03 ","")&IF(AQ7=1,"BLK-04 ","")&IF(AR7=1,"BLK-05 ","")&IF(AS7=1,"BLK-06 ","")) | AV7: =TRIM(IF(AN7=1,"BLK-01: No primary power | ","")&IF(AO7=1,"BLK-02: No connectivity / <2 Mbps | ","")&IF(AP7=1,"BLK-03: Zero computers or tablets | ","")&IF(AQ7=1,"BLK-04: Not reporting to DHIS2 | ","")&IF(AR7=1,"BLK-05: No IT support | ","")&IF(AS7=1,"BLK-06: Not operational | ","")) | AW7: =ROUND((AH7*22+AI7*18+AJ7*13+AK7*22+AL7*15+AM7*10)/300*100,1) -> 60.7 | AX7: =IF(AT7>0,"Tier 3",IF(AW7>=75,"Tier 1","Tier 2")) -> Tier 2 | AY7: =IF(AT7>0,"—",IF(AW7>=75,"Wave 1","Wave 2")) -> Wave 2
A8: ='1. Data - Facilities'!A8 -> Cotton Tree Health Center | B8: ='1. Data - Facilities'!B8 -> Margibi | C8: ='1. Data - Facilities'!C8 -> Health Center | D8: ='1. Data - Facilities'!F8 -> Grid | E8: ='1. Data - Facilities'!G8 -> 12 | F8: ='1. Data - Facilities'!H8 | G8: ='1. Data - Facilities'!I8 -> Generator only | H8: ='1. Data - Facilities'!J8 | I8: ='1. Data - Facilities'!K8 | J8: ='1. Data - Facilities'!L8 | K8: ='1. Data - Facilities'!M8 | ... Z8: ='1. Data - Facilities'!AB8 -> Yes | AA8: ='4. Aggregate - Literacy'!C8 -> 77 | AB8: ='4. Aggregate - Literacy'!B8 -> 3 | AC8: ='5. Aggregate - Sentiment'!C8 -> 6 | AD8: ='5. Aggregate - Sentiment'!B8 -> 4 | AE8: =IF(AND(AA8<>"",AB8>=3),AA8,R8) -> 77 | AF8: =N8+O8+P8 -> 0 | AG8: =IF(H8="","Mobile-only",IF(I8="","-",IF(I8>20,"High",IF(I8>=5,"Moderate","Low")))) -> Mobile-only | AH8: =IF(OR(D8="",D8="None"),0,IF(AND(OR(D8="Grid",D8="Solar / Inverter"),E8<>"",E8<4,F8="All critical workstations"),3,IF(AND(E8<>"",E8>15,OR(G8="",G8="None")),1,IF(AND(D8="Generator",OR(G8="",G8="None")),1,IF(AND(OR(D8="Grid",D8="Solar / Inverter",D8="Generator"),OR(AND(G8<>"",G8<>"None"),AND(E8<>"",E8<=15))),2,1))))) -> 2 | AI8: =IF(AND(H8="",OR(LEFT(M8,4)="None",M8="")),0,IF(AND(H8<>"",I8<>"",I8<2),0,IF(AND(H8<>"",I8<>""),IF(AND(I8>20,J8<>"",J8>10,OR(K8="",K8>=90),ISNUMBER(SEARCH("Low",L8))),3,IF(I8>=5,2,1)),IF(OR(LEFT(M8,5)="Stron",LEFT(M8,4)="Mode"),2,IF(LEFT(M8,4)="Weak",1,1))))) -> 2 | AJ8: =IF(AND(N8+O8=0,P8=0),0,IF(OR(N8+O8>=3,P8>=5),IF(Q8>0,3,2),IF(OR(N8+O8>=1,P8>=2),2,1))) -> 0 | AK8: =IF(AND(ISNUMBER(AE8),AE8>=70,S8<>"Some Clinicians",LEFT(T8,3)="Yes"),3,IF(AND(ISNUMBER(AE8),AE8>=50),2,1)) -> 2 | AL8: =IF(AND(ISNUMBER(AC8),AC8>=5),2,IF(AND(ISNUMBER(AC8),AC8>=3),1,1)) -> 2 | AM8: =IF(AND(OR(ISNUMBER(SEARCH("Hybrid",V8)),ISNUMBER(SEARCH("Digital",V8))),ISNUMBER(SEARCH(">=90",W8)),ISNUMBER(SEARCH("routinely",X8))),3,IF(AND(ISNUMBER(SEARCH("Yes",X8)),OR(ISNUMBER(SEARCH("70-89",W8)),ISNUMBER(SEARCH(">=90",W8)))),2,IF(OR(ISNUMBER(SEARCH("Inconsistently",X8)),ISNUMBER(SEARCH("70-89",W8))),2,IF(ISNUMBER(SEARCH("No unique",X8)),1,1)))) -> 2 | AN8: =IF(AH8=0,1,0) -> 0 | AO8: =IF(AI8=0,1,0) -> 0 | AP8: =IF(AJ8=0,1,0) -> 1 | AQ8: =IF(Y8="No",1,0) -> 0 | AR8: =IF(AND(T8="No",U8=""),1,0) -> 1 | AS8: =IF(Z8<>"Yes",1,0) -> 0 | AT8: =SUM(AN8:AS8) -> 2 | AU8: =TRIM(IF(AN8=1,"BLK-01 ","")&IF(AO8=1,"BLK-02 ","")&IF(AP8=1,"BLK-03 ","")&IF(AQ8=1,"BLK-04 ","")&IF(AR8=1,"BLK-05 ","")&IF(AS8=1,"BLK-06 ","")) -> BLK-03 BLK-05 | AV8: =TRIM(IF(AN8=1,"BLK-01: No primary power | ","")&IF(AO8=1,"BLK-02: No connectivity / <2 Mbps | ","")&IF(AP8=1,"BLK-03: Zero computers or tablets | ","")&IF(AQ8=1,"BLK-04: Not reporting to DHIS2 | ","")&IF(AR8=1,"BLK-05: No IT support | ","")&IF(AS8=1,"BLK-06: Not operational | ","")) -> BLK-03: Zero computers or tablets | BLK-05: No IT support | | AW8: =ROUND((AH8*22+AI8*18+AJ8*13+AK8*22+AL8*15+AM8*10)/300*100,1) -> 58 | AX8: =IF(AT8>0,"Tier 3",IF(AW8>=75,"Tier 1","Tier 2")) -> Tier 3 | AY8: =IF(AT8>0,"—",IF(AW8>=75,"Wave 1","Wave 2")) -> —
A9: ='1. Data - Facilities'!A9 -> Damballa Health Center | B9: ='1. Data - Facilities'!B9 -> Grand Cape Mount | C9: ='1. Data - Facilities'!C9 -> Health Center | D9: ='1. Data - Facilities'!F9 -> Solar / Inverter | E9: ='1. Data - Facilities'!G9 -> 8 | F9: ='1. Data - Facilities'!H9 | G9: ='1. Data - Facilities'!I9 | H9: ='1. Data - Facilities'!J9 | I9: ='1. Data - Facilities'!K9 | J9: ='1. Data - Facilities'!L9 | K9: ='1. Data - Facilities'!M9 | ... Z9: ='1. Data - Facilities'!AB9 -> Yes | AA9: ='4. Aggregate - Literacy'!C9 -> 60 | AB9: ='4. Aggregate - Literacy'!B9 -> 3 | AC9: ='5. Aggregate - Sentiment'!C9 -> 5.3 | AD9: ='5. Aggregate - Sentiment'!B9 -> 9 | AE9: =IF(AND(AA9<>"",AB9>=3),AA9,R9) -> 60 | AF9: =N9+O9+P9 -> 1 | AG9: =IF(H9="","Mobile-only",IF(I9="","-",IF(I9>20,"High",IF(I9>=5,"Moderate","Low")))) -> Mobile-only | AH9: =IF(OR(D9="",D9="None"),0,IF(AND(OR(D9="Grid",D9="Solar / Inverter"),E9<>"",E9<4,F9="All critical workstations"),3,IF(AND(E9<>"",E9>15,OR(G9="",G9="None")),1,IF(AND(D9="Generator",OR(G9="",G9="None")),1,IF(AND(OR(D9="Grid",D9="Solar / Inverter",D9="Generator"),OR(AND(G9<>"",G9<>"None"),AND(E9<>"",E9<=15))),2,1))))) -> 2 | AI9: =IF(AND(H9="",OR(LEFT(M9,4)="None",M9="")),0,IF(AND(H9<>"",I9<>"",I9<2),0,IF(AND(H9<>"",I9<>""),IF(AND(I9>20,J9<>"",J9>10,OR(K9="",K9>=90),ISNUMBER(SEARCH("Low",L9))),3,IF(I9>=5,2,1)),IF(OR(LEFT(M9,5)="Stron",LEFT(M9,4)="Mode"),2,IF(LEFT(M9,4)="Weak",1,1))))) -> 1 | AJ9: =IF(AND(N9+O9=0,P9=0),0,IF(OR(N9+O9>=3,P9>=5),IF(Q9>0,3,2),IF(OR(N9+O9>=1,P9>=2),2,1))) -> 2 | AK9: =IF(AND(ISNUMBER(AE9),AE9>=70,S9<>"Some Clinicians",LEFT(T9,3)="Yes"),3,IF(AND(ISNUMBER(AE9),AE9>=50),2,1)) -> 2 | AL9: =IF(AND(ISNUMBER(AC9),AC9>=5),2,IF(AND(ISNUMBER(AC9),AC9>=3),1,1)) -> 2 | AM9: =IF(AND(OR(ISNUMBER(SEARCH("Hybrid",V9)),ISNUMBER(SEARCH("Digital",V9))),ISNUMBER(SEARCH(">=90",W9)),ISNUMBER(SEARCH("routinely",X9))),3,IF(AND(ISNUMBER(SEARCH("Yes",X9)),OR(ISNUMBER(SEARCH("70-89",W9)),ISNUMBER(SEARCH(">=90",W9)))),2,IF(OR(ISNUMBER(SEARCH("Inconsistently",X9)),ISNUMBER(SEARCH("70-89",W9))),2,IF(ISNUMBER(SEARCH("No unique",X9)),1,1)))) -> 1 | AN9: =IF(AH9=0,1,0) -> 0 | AO9: =IF(AI9=0,1,0) -> 0 | AP9: =IF(AJ9=0,1,0) -> 0 | AQ9: =IF(Y9="No",1,0) -> 0 | AR9: =IF(AND(T9="No",U9=""),1,0) -> 1 | AS9: =IF(Z9<>"Yes",1,0) -> 0 | AT9: =SUM(AN9:AS9) -> 1 | AU9: =TRIM(IF(AN9=1,"BLK-01 ","")&IF(AO9=1,"BLK-02 ","")&IF(AP9=1,"BLK-03 ","")&IF(AQ9=1,"BLK-04 ","")&IF(AR9=1,"BLK-05 ","")&IF(AS9=1,"BLK-06 ","")) -> BLK-05 | AV9: =TRIM(IF(AN9=1,"BLK-01: No primary power | ","")&IF(AO9=1,"BLK-02: No connectivity / <2 Mbps | ","")&IF(AP9=1,"BLK-03: Zero computers or tablets | ","")&IF(AQ9=1,"BLK-04: Not reporting to DHIS2 | ","")&IF(AR9=1,"BLK-05: No IT support | ","")&IF(AS9=1,"BLK-06: Not operational | ","")) -> BLK-05: No IT support | | AW9: =ROUND((AH9*22+AI9*18+AJ9*13+AK9*22+AL9*15+AM9*10)/300*100,1) -> 57.3 | AX9: =IF(AT9>0,"Tier 3",IF(AW9>=75,"Tier 1","Tier 2")) -> Tier 3 | AY9: =IF(AT9>0,"—",IF(AW9>=75,"Wave 1","Wave 2")) -> —
A10: ='1. Data - Facilities'!A10 -> Dolo's Town Health Center | B10: ='1. Data - Facilities'!B10 -> Margibi | C10: ='1. Data - Facilities'!C10 -> Health Center | D10: ='1. Data - Facilities'!F10 -> Grid | E10: ='1. Data - Facilities'!G10 -> 12 | F10: ='1. Data - Facilities'!H10 | G10: ='1. Data - Facilities'!I10 -> Generator only | H10: ='1. Data - Facilities'!J10 | I10: ='1. Data - Facilities'!K10 | J10: ='1. Data - Facilities'!L10 | K10: ='1. Data - Facilities'!M10 | ... Z10: ='1. Data - Facilities'!AB10 -> Yes | AA10: ='4. Aggregate - Literacy'!C10 -> 67 | AB10: ='4. Aggregate - Literacy'!B10 -> 3 | AC10: ='5. Aggregate - Sentiment'!C10 -> 7.3 | AD10: ='5. Aggregate - Sentiment'!B10 -> 6 | AE10: =IF(AND(AA10<>"",AB10>=3),AA10,R10) -> 67 | AF10: =N10+O10+P10 -> 5 | AG10: =IF(H10="","Mobile-only",IF(I10="","-",IF(I10>20,"High",IF(I10>=5,"Moderate","Low")))) -> Mobile-only | AH10: =IF(OR(D10="",D10="None"),0,IF(AND(OR(D10="Grid",D10="Solar / Inverter"),E10<>"",E10<4,F10="All critical workstations"),3,IF(AND(E10<>"",E10>15,OR(G10="",G10="None")),1,IF(AND(D10="Generator",OR(G10="",G10="None")),1,IF(AND(OR(D10="Grid",D10="Solar / Inverter",D10="Generator"),OR(AND(G10<>"",G10<>"None"),AND(E10<>"",E10<=15))),2,1))))) -> 2 | AI10: =IF(AND(H10="",OR(LEFT(M10,4)="None",M10="")),0,IF(AND(H10<>"",I10<>"",I10<2),0,IF(AND(H10<>"",I10<>""),IF(AND(I10>20,J10<>"",J10>10,OR(K10="",K10>=90),ISNUMBER(SEARCH("Low",L10))),3,IF(I10>=5,2,1)),IF(OR(LEFT(M10,5)="Stron",LEFT(M10,4)="Mode"),2,IF(LEFT(M10,4)="Weak",1,1))))) -> 2 | AJ10: =IF(AND(N10+O10=0,P10=0),0,IF(OR(N10+O10>=3,P10>=5),IF(Q10>0,3,2),IF(OR(N10+O10>=1,P10>=2),2,1))) -> 2 | AK10: =IF(AND(ISNUMBER(AE10),AE10>=70,S10<>"Some Clinicians",LEFT(T10,3)="Yes"),3,IF(AND(ISNUMBER(AE10),AE10>=50),2,1)) -> 2 | AL10: =IF(AND(ISNUMBER(AC10),AC10>=5),2,IF(AND(ISNUMBER(AC10),AC10>=3),1,1)) -> 2 | AM10: =IF(AND(OR(ISNUMBER(SEARCH("Hybrid",V10)),ISNUMBER(SEARCH("Digital",V10))),ISNUMBER(SEARCH(">=90",W10)),ISNUMBER(SEARCH("routinely",X10))),3,IF(AND(ISNUMBER(SEARCH("Yes",X10)),OR(ISNUMBER(SEARCH("70-89",W10)),ISNUMBER(SEARCH(">=90",W10)))),2,IF(OR(ISNUMBER(SEARCH("Inconsistently",X10)),ISNUMBER(SEARCH("70-89",W10))),2,IF(ISNUMBER(SEARCH("No unique",X10)),1,1)))) -> 2 | AN10: =IF(AH10=0,1,0) -> 0 | AO10: =IF(AI10=0,1,0) -> 0 | AP10: =IF(AJ10=0,1,0) -> 0 | AQ10: =IF(Y10="No",1,0) -> 0 | AR10: =IF(AND(T10="No",U10=""),1,0) -> 1 | AS10: =IF(Z10<>"Yes",1,0) -> 0 | AT10: =SUM(AN10:AS10) -> 1 | AU10: =TRIM(IF(AN10=1,"BLK-01 ","")&IF(AO10=1,"BLK-02 ","")&IF(AP10=1,"BLK-03 ","")&IF(AQ10=1,"BLK-04 ","")&IF(AR10=1,"BLK-05 ","")&IF(AS10=1,"BLK-06 ","")) -> BLK-05 | AV10: =TRIM(IF(AN10=1,"BLK-01: No primary power | ","")&IF(AO10=1,"BLK-02: No connectivity / <2 Mbps | ","")&IF(AP10=1,"BLK-03: Zero computers or tablets | ","")&IF(AQ10=1,"BLK-04: Not reporting to DHIS2 | ","")&IF(AR10=1,"BLK-05: No IT support | ","")&IF(AS10=1,"BLK-06: Not operational | ","")) -> BLK-05: No IT support | | AW10: =ROUND((AH10*22+AI10*18+AJ10*13+AK10*22+AL10*15+AM10*10)/300*100,1) -> 66.7 | AX10: =IF(AT10>0,"Tier 3",IF(AW10>=75,"Tier 1","Tier 2")) -> Tier 3 | AY10: =IF(AT10>0,"—",IF(AW10>=75,"Wave 1","Wave 2")) -> —
A11: ='1. Data - Facilities'!A11 -> Dr. Agnes Varis Health Center | B11: ='1. Data - Facilities'!B11 -> Montserrado | C11: ='1. Data - Facilities'!C11 -> Health Center | D11: ='1. Data - Facilities'!F11 -> Grid | E11: ='1. Data - Facilities'!G11 -> 18 | F11: ='1. Data - Facilities'!H11 | G11: ='1. Data - Facilities'!I11 -> Solar / Inverter only | H11: ='1. Data - Facilities'!J11 | I11: ='1. Data - Facilities'!K11 | J11: ='1. Data - Facilities'!L11 | K11: ='1. Data - Facilities'!M11 | ... Z11: ='1. Data - Facilities'!AB11 -> Yes | AA11: ='4. Aggregate - Literacy'!C11 -> 55 | AB11: ='4. Aggregate - Literacy'!B11 -> 2 | AC11: ='5. Aggregate - Sentiment'!C11 -> 8.8 | AD11: ='5. Aggregate - Sentiment'!B11 -> 4 | AE11: =IF(AND(AA11<>"",AB11>=3),AA11,R11) -> 55 | AF11: =N11+O11+P11 -> 1 | AG11: =IF(H11="","Mobile-only",IF(I11="","-",IF(I11>20,"High",IF(I11>=5,"Moderate","Low")))) -> Mobile-only | AH11: =IF(OR(D11="",D11="None"),0,IF(AND(OR(D11="Grid",D11="Solar / Inverter"),E11<>"",E11<4,F11="All critical workstations"),3,IF(AND(E11<>"",E11>15,OR(G11="",G11="None")),1,IF(AND(D11="Generator",OR(G11="",G11="None")),1,IF(AND(OR(D11="Grid",D11="Solar / Inverter",D11="Generator"),OR(AND(G11<>"",G11<>"None"),AND(E11<>"",E11<=15))),2,1))))) -> 2 | AI11: =IF(AND(H11="",OR(LEFT(M11,4)="None",M11="")),0,IF(AND(H11<>"",I11<>"",I11<2),0,IF(AND(H11<>"",I11<>""),IF(AND(I11>20,J11<>"",J11>10,OR(K11="",K11>=90),ISNUMBER(SEARCH("Low",L11))),3,IF(I11>=5,2,1)),IF(OR(LEFT(M11,5)="Stron",LEFT(M11,4)="Mode"),2,IF(LEFT(M11,4)="Weak",1,1))))) -> 2 | AJ11: =IF(AND(N11+O11=0,P11=0),0,IF(OR(N11+O11>=3,P11>=5),IF(Q11>0,3,2),IF(OR(N11+O11>=1,P11>=2),2,1))) -> 2 | AK11: =IF(AND(ISNUMBER(AE11),AE11>=70,S11<>"Some Clinicians",LEFT(T11,3)="Yes"),3,IF(AND(ISNUMBER(AE11),AE11>=50),2,1)) -> 2 | AL11: =IF(AND(ISNUMBER(AC11),AC11>=5),2,IF(AND(ISNUMBER(AC11),AC11>=3),1,1)) -> 2 | AM11: =IF(AND(OR(ISNUMBER(SEARCH("Hybrid",V11)),ISNUMBER(SEARCH("Digital",V11))),ISNUMBER(SEARCH(">=90",W11)),ISNUMBER(SEARCH("routinely",X11))),3,IF(AND(ISNUMBER(SEARCH("Yes",X11)),OR(ISNUMBER(SEARCH("70-89",W11)),ISNUMBER(SEARCH(">=90",W11)))),2,IF(OR(ISNUMBER(SEARCH("Inconsistently",X11)),ISNUMBER(SEARCH("70-89",W11))),2,IF(ISNUMBER(SEARCH("No unique",X11)),1,1)))) -> 2 | AN11: =IF(AH11=0,1,0) -> 0 | AO11: =IF(AI11=0,1,0) -> 0 | AP11: =IF(AJ11=0,1,0) -> 0 | AQ11: =IF(Y11="No",1,0) -> 1 | AR11: =IF(AND(T11="No",U11=""),1,0) -> 1 | AS11: =IF(Z11<>"Yes",1,0) -> 0 | AT11: =SUM(AN11:AS11) -> 2 | AU11: =TRIM(IF(AN11=1,"BLK-01 ","")&IF(AO11=1,"BLK-02 ","")&IF(AP11=1,"BLK-03 ","")&IF(AQ11=1,"BLK-04 ","")&IF(AR11=1,"BLK-05 ","")&IF(AS11=1,"BLK-06 ","")) -> BLK-04 BLK-05 | AV11: =TRIM(IF(AN11=1,"BLK-01: No primary power | ","")&IF(AO11=1,"BLK-02: No connectivity / <2 Mbps | ","")&IF(AP11=1,"BLK-03: Zero computers or tablets | ","")&IF(AQ11=1,"BLK-04: Not reporting to DHIS2 | ","")&IF(AR11=1,"BLK-05: No IT support | ","")&IF(AS11=1,"BLK-06: Not operational | ","")) -> BLK-04: Not reporting to DHIS2 | BLK-05: No IT support | | AW11: =ROUND((AH11*22+AI11*18+AJ11*13+AK11*22+AL11*15+AM11*10)/300*100,1) -> 66.7 | AX11: =IF(AT11>0,"Tier 3",IF(AW11>=75,"Tier 1","Tier 2")) -> Tier 3 | AY11: =IF(AT11>0,"—",IF(AW11>=75,"Wave 1","Wave 2")) -> —
